Workbook

Sheet 1. Instructions
C2: IT Department Budget Template Instructions
C4: The IT Department Budget Template is an Excel spreadsheet that can be used to develop your annual IT
C5: Department budget. There are four worksheet tabs:
C7: 1. Instructions
C8: Read the instructions on this first tab before using this template to develop your budget.
C10: 2. Monthly Worksheet
C11: This is the tab that you can use to enter the value for each of the budget line
C13: 3. Department Budget
C14: This is a summary of the budget : it will calculate automatically from the Monthly Worksheet
C18: Please note the following:
C19: Only input numbers into cells that have a blue font color

Sheet 2. Monthly Worksheet
A1: IT Department Budget | B1: Last Year's Budget | C1: Month 1 | D1: Month 2 | E1: Month 3 | F1: Month 4 | G1: Month 5 | H1: Month 6 | I1: Month 7 | J1: Month 8 | K1: Month 9 | L1: Month 10 | M1: Month 11 | N1: Month 12 | O1: TOTALS | P1: Comments/Assumptions
A2: Monthly Worksheet | B2: (Full Year) | C2: Jan | D2: Feb | E2: Mar | F2: Apr | G2: May | H2: Jun | I2: Jul | J2: Aug | K2: Sep | L2: Oct | M2: Nov | N2: Dec
A3: DEPARTMENT REVENUES
A4: Fees IT Charges for Services Performed | B4: =15000*12 -> 180000 | C4: $16,500 | D4: $16,500 | E4: $16,500 | F4: $16,500 | G4: $16,500 | H4: $16,500 | I4: $16,500 | J4: $16,500 | K4: $16,500 | L4: $16,500 | M4: $16,500 | N4: $16,500 | O4: 198000 | P4: 150$/Mth/Emp. Assumed 10% HC growth.
A5: Proceeds from Sales of Assets | B5: 20000 | C5: 0 | D5: 0 | E5: 0 | F5: 0 | G5: 0 | H5: 0 | I5: 0 | J5: 0 | K5: 0 | L5: 0 | M5: 0 | N5: 0 | O5: 0 | P5: Obsolete assets to be givent to schools.
A6: Other | O6: =SUM(C6:N6) -> 0
A7: Total Department Revenue | B7: =SUM(B4:B6) -> 200000 | C7: =SUM(C4:C6) -> 0 | D7: =SUM(D4:D6) -> 0 | E7: =SUM(E4:E6) -> 0 | F7: =SUM(F4:F6) -> 0 | G7: =SUM(G4:G6) -> 0 | H7: =SUM(H4:H6) -> 0 | I7: =SUM(I4:I6) -> 0 | ... N7: =SUM(N4:N6) -> 0 | O7: =SUM(C7:N7) -> 0
A9: PERSONNEL
A10: Headcount (People not Dollars)
A11: Full-Time | B11: 5 | C11: 6 | D11: 6 | E11: 6 | F11: 6 | G11: 6 | H11: 6 | I11: 6 | J11: 6 | K11: 6 | L11: 6 | M11: 6 | N11: 6
A12: Contract | B12: 3 | C12: 3 | D12: 3 | E12: 3 | F12: 3 | G12: 3 | H12: 8 | I12: 8 | J12: 8 | K12: 8 | L12: 8 | M12: 8 | N12: 3
A13: Other | C13: 0 | D13: 0 | E13: 1 | F13: 1 | G13: 1 | H13: 1 | I13: 1 | J13: 1 | K13: 1 | L13: 1 | M13: 1 | N13: 1
A14: Total Headcount | B14: =SUM(B11:B13) -> 8 | C14: =SUM(C11:C13) -> 9 | D14: =SUM(D11:D13) -> 9 | E14: =SUM(E11:E13) -> 10 | F14: =SUM(F11:F13) -> 10 | G14: =SUM(G11:G13) -> 10 | H14: =SUM(H11:H13) -> 15 | I14: =SUM(I11:I13) -> 15 | ... N14: =SUM(N11:N13) -> 10
A16: DEPARTMENT EXPENSES
A17: Personnel Expenses (Dollars not People)
A18: Full-Time Salaries | B18: 325000 | C18: =K10 -> 0 | D18: =D11*5400 -> 32400 | E18: =E11*5400 -> 32400 | F18: =F11*5400 -> 32400 | G18: =G11*5400 -> 32400 | H18: =H11*5400 -> 32400 | I18: =I11*5400 -> 32400 | J18: =J11*5400 -> 32400 | K18: =K11*5400 -> 32400 | ... N18: =N11*5400 -> 32400 | O18: =SUM(C18:N18) -> 356400
A19: Temporary Workers | O19: =SUM(C19:N19) -> 0
A20: Bonuses / Other Compensation | B20: 40000 | O20: =SUM(C20:N20) -> 0
A21: Employee Benefits | C21: =C11*120 -> 720 | D21: =D11*120 -> 720 | E21: =E11*120 -> 720 | F21: =F11*120 -> 720 | G21: =G11*120 -> 720 | H21: =H11*120 -> 720 | I21: =I11*120 -> 720 | J21: =J11*120 -> 720 | ... N21: =N11*120 -> 720 | O21: =SUM(C21:N21) -> 8640
A22: Consultants | C22: =C13*10000 -> 0 | D22: =D13*10000 -> 0 | E22: =E13*10000 -> 10000 | F22: =F13*10000 -> 10000 | G22: =G13*10000 -> 10000 | H22: =H13*10000 -> 10000 | I22: =I13*10000 -> 10000 | J22: =J13*10000 -> 10000 | ... N22: =N13*10000 -> 10000 | O22: =SUM(C22:N22) -> 100000
A23: Outsourcing Contracts | B23: 255000 | C23: =C12*85000/12 -> 21250 | D23: =D12*85000/12 -> 21250 | E23: =E12*85000/12 -> 21250 | F23: =F12*85000/12 -> 21250 | G23: =G12*85000/12 -> 21250 | H23: =H12*85000/12 -> 56666.667 | I23: =I12*85000/12 -> 56666.667 | J23: =J12*85000/12 -> 56666.667 | ... N23: =N12*85000/12 -> 21250 | O23: =SUM(C23:N23) -> 467500
A24: Training / Seminars | O24: =SUM(C24:N24) -> 0
A25: Automobile Expense | O25: =SUM(C25:N25) -> 0
A26: Travel (e.g. Plane Tickets) | O26: =SUM(C26:N26) -> 0
A27: Accomodation (e.g. Hotels) | O27: =SUM(C27:N27) -> 0
A28: Meals | O28: =SUM(C28:N28) -> 0
A29: Employee Relocation | O29: =SUM(C29:N29) -> 0
A30: Total Personnel Expenses | B30: =SUM(B18:B29) -> 620000 | C30: =SUM(C18:C29) -> 21970 | D30: =SUM(D18:D29) -> 54370 | E30: =SUM(E18:E29) -> 64370 | F30: =SUM(F18:F29) -> 64370 | G30: =SUM(G18:G29) -> 64370 | H30: =SUM(H18:H29) -> 99786.667 | I30: =SUM(I18:I29) -> 99786.667 | ... N30: =SUM(N18:N29) -> 64370 | O30: =SUM(C30:N30) -> 932540
A32: Office Supplies
A33: General Supplies | O33: =SUM(C33:N33) -> 0
A34: Media Costs (Diskettes, CDs, Tapes, etc.) | O34: =SUM(C34:N34) -> 0
A35: Postage / Freight | O35: =SUM(C35:N35) -> 0
A36: Publication Costs | O36: =SUM(C36:N36) -> 0
A37: Total Office Supplies | B37: =SUM(B33:B36) -> 0 | C37: =SUM(C33:C36) -> 0 | D37: =SUM(D33:D36) -> 0 | E37: =SUM(E33:E36) -> 0 | F37: =SUM(F33:F36) -> 0 | G37: =SUM(G33:G36) -> 0 | H37: =SUM(H33:H36) -> 0 | I37: =SUM(I33:I36) -> 0 | ... N37: =SUM(N33:N36) -> 0 | O37: =SUM(C37:N37) -> 0
A39: Telecommunications Expenses
A40: Local Telephone | O40: =SUM(C40:N40) -> 0
A41: Long Distance | O41: =SUM(C41:N41) -> 0
A42: Cellular | O42: =SUM(C42:N42) -> 0
A43: Pagers | O43: =SUM(C43:N43) -> 0
A44: Communications Lines | O44: =SUM(C44:N44) -> 0
...

Sheet 3. Department Budget
A1: IT Department Budget | B1: Last Year's Budget | C1: This Year's Budget | D1: % of Total IT Spending | E1: % Change From Last Year | F1: Comments/Assumptions
A2: For Year Ending: | C2: (Total Year)
A3: DEPARTMENT REVENUES
A4: Fees IT Charges for Services Performed | B4: ='2. Monthly Worksheet'!B4 -> 180000 | C4: ='2. Monthly Worksheet'!O4 -> 198000 | D4: =IF(G4=0,G4,(C4/$C$95)) -> 0.21232333 | E4: =IF(H4=0,0,((C4-B4)/B4)) -> 0.1 | G4: =$C$95 -> 932540 | H4: =B4 -> 180000
A5: Proceeds from Sales of Assets | B5: ='2. Monthly Worksheet'!B5 -> 20000 | C5: ='2. Monthly Worksheet'!O5 -> 0 | D5: =IF(G5=0,G5,(C5/$C$95)) -> 0 | E5: =IF(H5=0,0,((C5-B5)/B5)) -> -1 | G5: =$C$95 -> 932540 | H5: =B5 -> 20000
A6: Other | B6: ='2. Monthly Worksheet'!B6 -> 0 | C6: ='2. Monthly Worksheet'!O6 -> 0 | D6: =IF(G6=0,G6,(C6/$C$95)) -> 0 | E6: =IF(H6=0,0,((C6-B6)/B6)) -> 0 | G6: =$C$95 -> 932540 | H6: =B6 -> 0
A7: Total Department Revenue | B7: =SUM(B4:B6) -> 200000 | C7: =SUM(C4:C6) -> 198000 | D7: =IF(G7=0,G7,(C7/$C$95)) -> 0.21232333 | E7: =IF(H7=0,0,((C7-B7)/B7)) -> -0.01 | G7: =$C$95 -> 932540 | H7: =B7 -> 200000
G8: =$C$95 -> 932540 | H8: =B8 -> 0
A9: PERSONNEL | G9: =$C$95 -> 932540 | H9: =B9 -> 0
A10: Headcount (People not Dollars) | G10: =$C$95 -> 932540 | H10: =B10 -> 0
A11: Full-Time | E11: =IF(H11=0,0,((C11-B11)/B11)) -> 0 | G11: =$C$95 -> 932540 | H11: =B11 -> 0
A12: Contract | E12: =IF(H12=0,0,((C12-B12)/B12)) -> 0 | G12: =$C$95 -> 932540 | H12: =B12 -> 0
A13: Other | E13: =IF(H13=0,0,((C13-B13)/B13)) -> 0 | G13: =$C$95 -> 932540 | H13: =B13 -> 0
A14: Total Headcount | B14: =SUM(B11:B13) -> 0 | C14: =SUM(C11:C13) -> 0 | E14: =IF(H14=0,0,((C14-B14)/B14)) -> 0 | G14: =$C$95 -> 932540 | H14: =B14 -> 0
A16: DEPARTMENT EXPENSES | G16: =$C$95 -> 932540 | H16: =B16 -> 0
A17: Personnel Expenses (Dollars not People) | G17: =$C$95 -> 932540 | H17: =B17 -> 0
A18: Full-Time Salaries | B18: ='2. Monthly Worksheet'!B18 -> 325000 | C18: ='2. Monthly Worksheet'!O18 -> 356400 | D18: =IF(G18=0,G18,(C18/$C$95)) -> 0.382182 | E18: =IF(H18=0,0,((C18-B18)/B18)) -> 0.096615385 | G18: =$C$95 -> 932540 | H18: =B18 -> 325000
A19: Temporary Workers | B19: ='2. Monthly Worksheet'!B19 -> 0 | C19: ='2. Monthly Worksheet'!O19 -> 0 | D19: =IF(G19=0,G19,(C19/$C$95)) -> 0 | E19: =IF(H19=0,0,((C19-B19)/B19)) -> 0 | G19: =$C$95 -> 932540 | H19: =B19 -> 0
A20: Bonuses / Other Compensation | B20: ='2. Monthly Worksheet'!B20 -> 40000 | C20: ='2. Monthly Worksheet'!O20 -> 0 | D20: =IF(G20=0,G20,(C20/$C$95)) -> 0 | E20: =IF(H20=0,0,((C20-B20)/B20)) -> -1 | G20: =$C$95 -> 932540 | H20: =B20 -> 40000
A21: Employee Benefits | B21: ='2. Monthly Worksheet'!B21 -> 0 | C21: ='2. Monthly Worksheet'!O21 -> 8640 | D21: =IF(G21=0,G21,(C21/$C$95)) -> 0.0092650181 | E21: =IF(H21=0,0,((C21-B21)/B21)) -> 0 | G21: =$C$95 -> 932540 | H21: =B21 -> 0
A22: Consultants | B22: ='2. Monthly Worksheet'!B22 -> 0 | C22: ='2. Monthly Worksheet'!O22 -> 100000 | D22: =IF(G22=0,G22,(C22/$C$95)) -> 0.10723401 | E22: =IF(H22=0,0,((C22-B22)/B22)) -> 0 | G22: =$C$95 -> 932540 | H22: =B22 -> 0
A23: Outsourcing Contracts | B23: ='2. Monthly Worksheet'!B23 -> 255000 | C23: ='2. Monthly Worksheet'!O23 -> 467500 | D23: =IF(G23=0,G23,(C23/$C$95)) -> 0.50131898 | E23: =IF(H23=0,0,((C23-B23)/B23)) -> 0.83333333 | G23: =$C$95 -> 932540 | H23: =B23 -> 255000
A24: Training / Seminars | B24: ='2. Monthly Worksheet'!B24 -> 0 | C24: ='2. Monthly Worksheet'!O24 -> 0 | D24: =IF(G24=0,G24,(C24/$C$95)) -> 0 | E24: =IF(H24=0,0,((C24-B24)/B24)) -> 0 | G24: =$C$95 -> 932540 | H24: =B24 -> 0
A25: Automobile Expense | B25: ='2. Monthly Worksheet'!B25 -> 0 | C25: ='2. Monthly Worksheet'!O25 -> 0 | D25: =IF(G25=0,G25,(C25/$C$95)) -> 0 | E25: =IF(H25=0,0,((C25-B25)/B25)) -> 0 | G25: =$C$95 -> 932540 | H25: =B25 -> 0
A26: Travel (e.g. Plane Tickets) | B26: ='2. Monthly Worksheet'!B26 -> 0 | C26: ='2. Monthly Worksheet'!O26 -> 0 | D26: =IF(G26=0,G26,(C26/$C$95)) -> 0 | E26: =IF(H26=0,0,((C26-B26)/B26)) -> 0 | G26: =$C$95 -> 932540 | H26: =B26 -> 0
A27: Accomodation (e.g. Hotels) | B27: ='2. Monthly Worksheet'!B27 -> 0 | C27: ='2. Monthly Worksheet'!O27 -> 0 | D27: =IF(G27=0,G27,(C27/$C$95)) -> 0 | E27: =IF(H27=0,0,((C27-B27)/B27)) -> 0 | G27: =$C$95 -> 932540 | H27: =B27 -> 0
A28: Meals | B28: ='2. Monthly Worksheet'!B28 -> 0 | C28: ='2. Monthly Worksheet'!O28 -> 0 | D28: =IF(G28=0,G28,(C28/$C$95)) -> 0 | E28: =IF(H28=0,0,((C28-B28)/B28)) -> 0 | G28: =$C$95 -> 932540 | H28: =B28 -> 0
A29: Employee Relocation | B29: ='2. Monthly Worksheet'!B29 -> 0 | C29: ='2. Monthly Worksheet'!O29 -> 0 | D29: =IF(G29=0,G29,(C29/$C$95)) -> 0 | E29: =IF(H29=0,0,((C29-B29)/B29)) -> 0 | G29: =$C$95 -> 932540 | H29: =B29 -> 0
A30: Total Personnel Expenses | B30: =SUM(B18:B29) -> 620000 | C30: =SUM(C18:C29) -> 932540 | D30: =IF(G30=0,G30,(C30/$C$95)) -> 1 | E30: =IF(H30=0,0,((C30-B30)/B30)) -> 0.50409677 | G30: =$C$95 -> 932540 | H30: =B30 -> 620000
G31: =$C$95 -> 932540 | H31: =B31 -> 0
A32: Office Supplies | G32: =$C$95 -> 932540 | H32: =B32 -> 0
A33: General Supplies | B33: ='2. Monthly Worksheet'!B33 -> 0 | C33: ='2. Monthly Worksheet'!O33 -> 0 | D33: =IF(G33=0,G33,(C33/$C$95)) -> 0 | E33: =IF(H33=0,0,((C33-B33)/B33)) -> 0 | G33: =$C$95 -> 932540 | H33: =B33 -> 0
A34: Media Costs (Diskettes, CDs, Tapes, etc.) | B34: ='2. Monthly Worksheet'!B34 -> 0 | C34: ='2. Monthly Worksheet'!O34 -> 0 | D34: =IF(G34=0,G34,(C34/$C$95)) -> 0 | E34: =IF(H34=0,0,((C34-B34)/B34)) -> 0 | G34: =$C$95 -> 932540 | H34: =B34 -> 0
A35: Postage / Freight | B35: ='2. Monthly Worksheet'!B35 -> 0 | C35: ='2. Monthly Worksheet'!O35 -> 0 | D35: =IF(G35=0,G35,(C35/$C$95)) -> 0 | E35: =IF(H35=0,0,((C35-B35)/B35)) -> 0 | G35: =$C$95 -> 932540 | H35: =B35 -> 0
A36: Publication Costs | B36: ='2. Monthly Worksheet'!B36 -> 0 | C36: ='2. Monthly Worksheet'!O36 -> 0 | D36: =IF(G36=0,G36,(C36/$C$95)) -> 0 | E36: =IF(H36=0,0,((C36-B36)/B36)) -> 0 | G36: =$C$95 -> 932540 | H36: =B36 -> 0
A37: Total Office Supplies | B37: =SUM(B33:B36) -> 0 | C37: =SUM(C33:C36) -> 0 | D37: =IF(G37=0,G37,(C37/$C$95)) -> 0 | E37: =IF(H37=0,0,((C37-B37)/B37)) -> 0 | G37: =$C$95 -> 932540 | H37: =B37 -> 0
G38: =$C$95 -> 932540 | H38: =B38 -> 0
A39: Telecommunications Expenses | G39: =$C$95 -> 932540 | H39: =B39 -> 0
A40: Local Telephone | B40: ='2. Monthly Worksheet'!B40 -> 0 | C40: ='2. Monthly Worksheet'!O40 -> 0 | D40: =IF(G40=0,G40,(C40/$C$95)) -> 0 | E40: =IF(H40=0,0,((C40-B40)/B40)) -> 0 | G40: =$C$95 -> 932540 | H40: =B40 -> 0
A41: Long Distance | B41: ='2. Monthly Worksheet'!B41 -> 0 | C41: ='2. Monthly Worksheet'!O41 -> 0 | D41: =IF(G41=0,G41,(C41/$C$95)) -> 0 | E41: =IF(H41=0,0,((C41-B41)/B41)) -> 0 | G41: =$C$95 -> 932540 | H41: =B41 -> 0
...
